<?xml version="1.0" encoding="utf-8"?>
<!-- This URDF was automatically created by SolidWorks to URDF Exporter! Originally created by Stephen Brawner (brawner@gmail.com) 
     Commit Version: 1.6.0-4-g7f85cfe  Build Version: 1.6.7995.38578
     For more information, please see http://wiki.ros.org/sw_urdf_exporter -->
<robot
  name="hospital_bot">

  <link name="base_footprint"/>

  <link
    name="base_link">
    <inertial>
      <origin
        xyz="0.046938 0 0.36047"
        rpy="0 0 0" />
      <mass
        value="42" />
      <inertia
        ixx="5.0301"
        ixy="-0.00018229"
        ixz="-0.73275"
        iyy="5.2375"
        iyz="-0.0002395"
        izz="1.8786" />
    </inertial>
    <visual>
      <origin
        xyz="0 0 -0.002"
        rpy="0 0 0" />
      <geometry>
        <mesh
          filename="package://hospital_bot/description/meshes/stl/base_link.STL" />
      </geometry>
      <material
        name="">
        <color
          rgba="0.79216 0.81961 0.93333 1" />
      </material>
    </visual>
    <collision>
      <origin
        xyz="0 0 -0.002"
        rpy="0 0 0" />
      <geometry>
        <mesh
          filename="package://hospital_bot/description/meshes/stl/base_link.STL" />
      </geometry>
    </collision>
  </link>


  <link
    name="wheel_r">
    <inertial>
      <origin
        xyz="-0.0321811166739466 0 0"
        rpy="0 0 0" />
      <mass
        value="2" />
      <inertia
        ixx="0.000779700589773781"
        ixy="0"
        ixz="0"
        iyy="0.000422843653180422"
        iyz="0"
        izz="0.00042284916188285" />
    </inertial>
    <visual>
      <origin
        xyz="0 0 0"
        rpy="0 0 0" />
      <geometry>
        <mesh
          filename="package://hospital_bot/description/meshes/stl/wheel_r.STL" />
      </geometry>
      <material
        name="Rubber">
        <color
          rgba="0.792156862745098 0.819607843137255 0.933333333333333 1" />
      </material>
    </visual>
    <collision>
      <origin
        xyz="0 0 0"
        rpy="0 0 0" />
      <geometry>
        <mesh
          filename="package://hospital_bot/description/meshes/stl/wheel_r.STL" />
      </geometry>
    </collision>
  </link>
  
  <link
    name="lidar">
    <inertial>
      <origin
        xyz="0.000565454433332113 0 0.0192985480594141"
        rpy="0 0 0" />
      <mass
        value="0.7" />
      <inertia
        ixx="0"
        ixy="0"
        ixz="0"
        iyy="0"
        iyz="0"
        izz="0.000109946753058708" />
    </inertial>
    <visual>
      <origin
        xyz="0 0 0"
        rpy="0 0 0" />
      <geometry>
        <mesh
          filename="package://hospital_bot/description/meshes/stl/lidar.STL" />
      </geometry>
      <material
        name="">
        <color
          rgba="0.752941176470588 0.752941176470588 0.752941176470588 0.4" />
      </material>
    </visual>
    <collision>
      <origin
        xyz="0 0 0"
        rpy="0 0 0" />
      <geometry>
        <mesh
          filename="package://hospital_bot/description/meshes/stl/lidar.STL" />
      </geometry>
    </collision>
  </link>
  
  <link
    name="camera">
    <inertial>
      <origin
        xyz="-0.0197753693988049 0.0075270431497297 -0.00225150612347791"
        rpy="0 0 0" />
      <mass
        value="0.3" />
      <inertia
        ixx="0"
        ixy="0"
        ixz="0"
        iyy="0"
        iyz="0"
        izz="0" />
    </inertial>
    <visual>
      <origin
        xyz="0 0 0"
        rpy="0 0 0" />
      <geometry>
        <mesh
          filename="package://hospital_bot/description/meshes/stl/camera.STL" />
      </geometry>
      <material
        name="">
        <color
          rgba="0 0 0 1" />
      </material>
    </visual>
    <collision>
      <origin
        xyz="0 0 0"
        rpy="0 0 0" />
      <geometry>
        <mesh
          filename="package://hospital_bot/description/meshes/stl/camera.STL" />
      </geometry>
    </collision>
  </link>
  
  <link
    name="surab">
    <inertial>
      <origin
        xyz="0 0.0906533712392535 0.0173397517103782"
        rpy="0 0 0" />
      <mass
        value="5" />
      <inertia
        ixx="0.899159538665213"
        ixy="0"
        ixz="0"
        iyy="1.73764210519367"
        iyz="0.000237785495740509"
        izz="1.06247031877449" />
    </inertial>
    <visual>
      <origin
        xyz="0 0 0"
        rpy="0 0 0" />
      <geometry>
        <mesh
          filename="package://hospital_bot/description/meshes/stl/surab.STL" />
      </geometry>
      <material
        name="">
        <color
          rgba="0.792156862745098 0.819607843137255 0.933333333333333 1" />
      </material>
    </visual>
    <collision>
      <origin
        xyz="0 0 0"
        rpy="0 0 0" />
      <geometry>
        <mesh
          filename="package://hospital_bot/description/meshes/stl/surab.STL" />
      </geometry>
    </collision>
  </link>
  
  <link
    name="sunban">
    <inertial>
      <origin
        xyz="-0.000793683288460259 0.25939148323271 -0.227271322564606"
        rpy="0 0 0" />
      <mass
        value="6" />
      <inertia
        ixx="0.289185444183791"
        ixy="0"
        ixz="0"
        iyy="0.663714612054266"
        iyz="-0.000232364840895673"
        izz="0.375647753963373" />
    </inertial>
    <visual>
      <origin
        xyz="0 0 0"
        rpy="0 0 0" />
      <geometry>
        <mesh
          filename="package://hospital_bot/description/meshes/stl/sunban.STL" />
      </geometry>
      <material
        name="">
        <color
          rgba="0 0 0 1" />
      </material>
    </visual>
    <collision>
      <origin
        xyz="0 0 0"
        rpy="0 0 0" />
      <geometry>
        <mesh
          filename="package://hospital_bot/description/meshes/stl/sunban.STL" />
      </geometry>
    </collision>
  </link>
  
  <link
    name="monitor">
    <inertial>
      <origin
        xyz="0 0.0250425722260409 -0.00395495330955042"
        rpy="0 0 0" />
      <mass
        value="2" />
      <inertia
        ixx="0.0022560414123335"
        ixy="0"
        ixz="0"
        iyy="0.00403859946143406"
        iyz="0"
        izz="0.00225779969468586" />
    </inertial>
    <visual>
      <origin
        xyz="0 0 0"
        rpy="0 0 0" />
      <geometry>
        <mesh
          filename="package://hospital_bot/description/meshes/stl/monitor.STL" />
      </geometry>
      <material
        name="">
        <color
          rgba="0.101960784313725 0.101960784313725 0.101960784313725 1" />
      </material>
    </visual>
    <collision>
      <origin
        xyz="0 0 0"
        rpy="0 0 0" />
      <geometry>
        <mesh
          filename="package://hospital_bot/description/meshes/stl/monitor.STL" />
      </geometry>
    </collision>
  </link>
  
  <link
    name="wheel_l">
    <inertial>
      <origin
        xyz="-0.0321811166739313 0 0"
        rpy="0 0 0" />
      <mass
        value="2" />
      <inertia
        ixx="0.000779700589774398"
        ixy="0"
        ixz="0"
        iyy="0.000422839949640887"
        iyz="0"
        izz="0.000422852865423091" />
    </inertial>
    <visual>
      <origin
        xyz="0 0 0"
        rpy="0 0 0" />
      <geometry>
        <mesh
          filename="package://hospital_bot/description/meshes/stl/wheel_l.STL" />
      </geometry>
      <material
        name="Rubber">
        <color
          rgba="0.792156862745098 0.819607843137255 0.933333333333333 1" />
      </material>
    </visual>
    <collision>
      <origin
        xyz="0 0 0"
        rpy="0 0 0" />
      <geometry>
        <mesh
          filename="package://hospital_bot/description/meshes/stl/wheel_l.STL" />
      </geometry>
    </collision>
  </link>


  <!-- for joint -->
  <joint name="base_footprint_to_base_link" 
    type="fixed">
    <parent link="base_footprint"/>
    <child link="base_link"/>
    <origin xyz="0 0 0.082" rpy="0 0 0"/>
  </joint>

  <joint
    name="joint_r"
    type="continuous">
    <origin
      xyz="-0.0016115 0.229 -0.020269"
      rpy="1.5708 0 1.5708" />
    <parent
      link="base_link" />
    <child
      link="wheel_r" />
    <axis
      xyz="1 0 0" />
    <!-- <limit
      lower="0"
      upper="0"
      effort="0"
      velocity="0" /> -->
  </joint>

  <joint
    name="joint_l"
    type="continuous">
    <origin
      xyz="-0.0016115 -0.229 -0.020269"
      rpy="0 0 -1.5708" />
    <parent
      link="base_link" />
    <child
      link="wheel_l" />
    <axis
      xyz="-1 0 0" />
    <!-- <limit
      lower="0"
      upper="0"
      effort="0"
      velocity="0" /> -->
  </joint>

  <joint
    name="joint_lidar"
    type="fixed">
    <origin
      xyz="0 0 0.23"
      rpy="0 0 0" />
    <parent
      link="base_link" />
    <child
      link="lidar" />
    <axis
      xyz="0 0 1" />
    <!-- <limit
      lower="0"
      upper="0"
      effort="0"
      velocity="0" /> -->
  </joint>

  <joint
    name="joint_camera"
    type="fixed">
    <origin
      xyz="0.246763183078283 -0.00833335958428078 0.941940271292447"
      rpy="0 0 0" />
    <parent
      link="base_link" />
    <child
      link="camera" />
    <axis
      xyz="0 0 0" />
  </joint>

  <joint
    name="surab_j"
    type="fixed">
    <origin
      xyz="0 0 0.41"
      rpy="1.5707963267949 0 -1.5707963267949" />
    <parent
      link="base_link" />
    <child
      link="surab" />
    <axis
      xyz="0 0 0" />
  </joint>

  <joint
    name="sunban_j"
    type="fixed">
    <origin
      xyz="-0.258690732424951 0 0.59"
      rpy="1.5707963267949 0 -1.5707963267949" />
    <parent
      link="base_link" />
    <child
      link="sunban" />
    <axis
      xyz="0 0 0" />
    <!-- <limit
      lower="0"
      upper="0"
      effort="0"
      velocity="0" /> -->
  </joint>

  <joint
    name="monitor_j"
    type="fixed">
    <origin
      xyz="0.0281145179893907 -0.000217843036471599 1.15678589269231"
      rpy="2.43763345715047 0 1.5707963267949" />
    <parent
      link="base_link" />
    <child
      link="monitor" />
    <axis
      xyz="0 0 0" />
  </joint>


  <!-- for gazebo -->


  <gazebo reference="base_link">
    <mu1>0.001</mu1>
    <mu2>0.001</mu2>
    <material>Gazebo/Orange</material>
  </gazebo>

  <gazebo reference="wheel_l">
    <mu1>0.7</mu1>
    <mu2>0.7</mu2>
    <kp>500000.0</kp>
    <kd>10.0</kd>
    <material>Gazebo/Black</material>
    </gazebo>

  <gazebo reference="wheel_r">
    <mu1>0.7</mu1>
    <mu2>0.7</mu2>
    <kp>500000.0</kp>
    <kd>10.0</kd>
    <material>Gazebo/Black</material>
  </gazebo>

  <gazebo reference="monitor">
    <material>Gazebo/Black</material>
  </gazebo>

  <gazebo reference="surab">
    <material>Gazebo/Grey</material>
  </gazebo>

  <gazebo reference="sunban">
    <material>Gazebo/White</material>
  </gazebo>



  <gazebo>
    <plugin name="differential_drive_controller" filename="libgazebo_ros_diff_drive.so">
      <alwaysOn>true</alwaysOn>
      <updateRate>20</updateRate>
      <legacyMode>false</legacyMode>
      <leftJoint>joint_r</leftJoint>
      <rightJoint>joint_l</rightJoint>
      <wheelSeparation>0.32</wheelSeparation>
      <wheelDiameter>0.136</wheelDiameter>
      <wheelTorque>3.2</wheelTorque>
      <wheelAcceleration>1</wheelAcceleration>
      <commandTopic>cmd_vel</commandTopic>
      <odometryTopic>odom</odometryTopic>
      <odometryFrame>odom</odometryFrame>
      <odometrySource>world</odometrySource>
      <publishOdomTF>true</publishOdomTF>
      <publishWheelJointState>true</publishWheelJointState>
      <publishWheelTF>false</publishWheelTF>
      <publishTf>true</publishTf>
      <robotBaseFrame>base_footprint</robotBaseFrame>
      <rosDebugLevel>na</rosDebugLevel>
    </plugin>
  </gazebo>  


  <!--cameral link-->
  <gazebo reference="camera">
    <sensor type="camera" name="camera1">
      <update_rate>30.0</update_rate>
      <camera name="head">
        <horizontal_fov>1.57</horizontal_fov>
        <image>
              <width>1280</width>
              <height>800</height>
              <format>R8G8B8</format>
            </image>
        <clip>
          <near>0.06</near>
          <far>600</far>
        </clip>
        <noise>
          <type>gaussian</type>
          <mean>0.0</mean>
          <stddev>0.007</stddev>
        </noise>
      </camera>
      <plugin name="camera_controller" filename="libgazebo_ros_camera.so">
        <alwaysOn>true</alwaysOn>
            <updateRate>0.0</updateRate>
            <cameraName>camera1</cameraName>
            <imageTopicName>image_raw</imageTopicName>
            <cameraInfoTopicName>camera_info</cameraInfoTopicName>
            <frameName>camera</frameName>
            <hackBaseline>0.07</hackBaseline>
            <distortionK1>0.0</distortionK1>
            <distortionK2>0.0</distortionK2>
            <distortionK3>0.0</distortionK3>
            <distortionT1>0.0</distortionT1>
            <distortionT2>0.0</distortionT2>
        </plugin>
    </sensor>
    <material>Gazebo/Black</material>
  </gazebo> 

  <gazebo reference="lidar">
    <material>Gazebo/Black</material>
    <sensor type="ray" name="head_hokuyo_sensor">
      <pose>0 0 0 0 0 0 </pose>
      <visualize>false</visualize>
      <update_rate>30</update_rate>
      <ray>
        <scan>
          <horizontal>
            <samples>720</samples>
            <resolution>1</resolution>
            <min_angle>-3.14</min_angle>
            <max_angle>3.14</max_angle>
          </horizontal>
        </scan>
        <range>
          <min>0.3</min>   
         <max>10.0</max>
          <resolution>0.01</resolution>
        </range>
        <noise>
          <type>gaussian</type>
          <mean>0.0</mean>
          <stddev>0.01</stddev>
        </noise>
      </ray>
      <plugin name="gazebo_ros_head_hokuyo_controller" filename="libgazebo_ros_laser.so">
        <topicName>/laser/scan</topicName>
        <frameName>lidar</frameName>
      </plugin>
    </sensor>
  </gazebo>
</robot>